Workbook

Sheet Read Me
A1: Villa Somalia Hybrid Plant: SCADA Bill of Material
A2: Project | B2: Solarization of Villa Somalia, Mogadishu. 1,516 kWp PV, 3,340 kWh BESS, 2 diesel generators, 11 kV switchboard, 2 office transformer stations.
A3: Basis | B3: SICAM A8000 design: SCADA Design Report Rev 1, Device and I/O List Rev 1, drawing set BFE/PR/26/01-SCADA-001 to 005.
A4: Status | B4: Rev A, 22 Oct 2026, for pricing and supplier quotations. Quantities fixed by the design; prices to be entered.
A5: Architecture | B5: Two CP-8050 in hot standby; six I/O rows (24 modules, 244 hardwired signals, 27 % spare); SICAM SCC on two servers by IEC 60870-5-104; managed fibre ring of 7 switches; one firewall with VPN off by default; GPS time.
A6: Sheets
A7: BOM by Panel | B7: Every item grouped by the panel or area it goes into, with tag, quantity and notes. Use it to build and check the panels.
A8: Summary | B8: The same items totalled per order line. Enter unit prices here, once; the BOM by Panel picks them up.
A9: IO Check | B9: I/O modules per row against the hardwired signals of the I/O list, with spare capacity.
A10: By Others | B10: Equipment that the SCADA connects to but does not supply, and what the SCADA needs from each supplier.
A11: Services | B11: Engineering and site services, for the offer. Not materials.
A12: Number status key
A13: Checked | B13: Ordering number found on a supplier listing or a Siemens configuration document.
A14: From memory - confirm | B14: Ordering code from knowledge of the maker's catalogue; not checked online. Confirm with the distributor.
A15: To confirm with supplier | B15: Product exists but its number was not found, or it is configured or licensed by quotation. Take it from the supplier.
A16: TBC | B16: Size, make or length not fixed yet. Shaded yellow.
A17: Assumptions and points to confirm
A18: 1 | B18: Control voltage 110 V DC for the controllers and I/O rows (selects PS-8642, CI-8532, CI-8533, DI-8112). Confirm that 110 V DC exists at the office stations, the BESS yard and the generator area. If only 230 V AC is available there, either add a 230 V AC to 110 V DC supply per panel or change those rows to the 24 V variants (CI-8531, DI-8110) fed from the SITOP.
A19: 2 | B19: Siemens to confirm: CI-8533 and DO-8221 ordering numbers, the hot standby function and licence, switchover time, and how the I/O rows connect to both controllers.
A20: 3 | B20: Network ordering codes (Moxa, Fortinet, Meinberg) are from memory. Siemens SCALANCE equivalents may be offered instead; keep the same port counts.
A21: 4 | B21: Field switches at the stations and yard use a 5 A SITOP instead of the 20 A unit of the Device List, which is oversized for one switch and one gateway.
A22: 5 | B22: Two items not in the Device List Rev 1 are added: a 19-inch server rack with console for the control room, and a small enclosure for SW-MV.
A23: 6 | B23: Cable and fibre lengths are left open until the cable route drawings are available.
A24: 7 | B24: Currency and prices: enter in the Summary sheet. Totals calculate automatically.

Sheet BOM by Panel
A1: Bill of material by panel – SICAM A8000 design
A2: Item | B2: Tag / use | C2: Description | D2: Manufacturer | E2: Model | F2: Order no. | G2: Number status | H2: Qty | I2: Unit | J2: Unit price | K2: Total price | L2: Location | M2: Notes | N2: Group | O2: Key
A3: P1 | B3: SCADA cabinet, 11 kV switchroom (controller pair, I/O rows 1 and 2, core network)
A4: P1.01 | B4: CP-8050 A, CP-8050 B | C4: Processor module, SICAM A8000 | D4: Siemens | E4: CP-8050 | F4: 6MF2805-0AA00 | G4: Checked | H4: 2 | I4: pc | J4: =IF(Summary!$I$3="","",Summary!$I$3) | K4: =IF(OR(J4="",H4=""),"",H4*J4) | L4: 11 kV switchroom | M4: Hot standby pair: A active, B standby. | N4: P1 | O4: CP8050
A5: P1.02 | B5: Two per controller | C5: Power supply 110-220 V DC, 45 W | D5: Siemens | E5: PS-8642 | F5: 6MF2864-2AA00 | G5: Checked | H5: 4 | I5: pc | J5: =IF(Summary!$I$4="","",Summary!$I$4) | K5: =IF(OR(J5="",H5=""),"",H5*J5) | L5: 11 kV switchroom | M5: Confirm the CP-8050 accepts a second supply. | N5: P1 | O5: PS8642
A6: P1.03 | B6: One per controller | C6: Ethernet interface, 5 x RJ45 | D6: Siemens | E6: CI-8520 | F6: 6MF2852-0AA00 | G6: Checked | H6: 2 | I6: pc | J6: =IF(Summary!$I$5="","",Summary!$I$5) | K6: =IF(OR(J6="",H6=""),"",H6*J6) | L6: 11 kV switchroom | M6: Separate port per network zone; not a switch. | N6: P1 | O6: CI8520
A7: P1.04 | B7: One per controller | C7: SICAM flash card, 2 GB | D7: Siemens | E7: SICAM flash card | F7: 6MF1213-1GA05-0AA0 | G7: Checked | H7: 2 | I7: pc | J7: =IF(Summary!$I$6="","",Summary!$I$6) | K7: =IF(OR(J7="",H7=""),"",H7*J7) | L7: 11 kV switchroom | N7: P1 | O7: FLASH
A8: P1.05 | B8: One set per controller | C8: Protocol licences for one CP-8050: IEC 60870-5-104 server, Modbus TCP client, IEC 61850 client, hot standby function | D8: Siemens | E8: CP-8050 licences | F8: By quotation | G8: To confirm with supplier | H8: 2 | I8: set | J8: =IF(Summary!$I$7="","",Summary!$I$7) | K8: =IF(OR(J8="",H8=""),"",H8*J8) | L8: 11 kV switchroom | M8: Including the hot standby function if licensed separately (open point 12). | N8: P1 | O8: LIC
A9: P1.06 | B9: Row 1 interface | C9: I/O remote interface, electrical, 110-220 V DC | D9: Siemens | E9: CI-8532 | F9: 6MF2853-2AA00 | G9: Checked | H9: 1 | I9: pc | J9: =IF(Summary!$I$8="","",Summary!$I$8) | K9: =IF(OR(J9="",H9=""),"",H9*J9) | L9: 11 kV switchroom | M9: Row 1 on its own interface so both controllers reach it. | N9: P1 | O9: CI8532
A10: P1.07 | B10: R1-DI01 to R1-DI05 | C10: Digital input, 2 x 8 inputs, 110 V DC | D10: Siemens | E10: DI-8112 | F10: 6MF2811-2AA00 | G10: Checked | H10: 5 | I10: pc | J10: =IF(Summary!$I$9="","",Summary!$I$9) | K10: =IF(OR(J10="",H10=""),"",H10*J10) | L10: 11 kV switchroom | M10: 11 kV panels AH1 to AH8. | N10: P1 | O10: DI8112
A11: P1.08 | B11: R1-CO01, R1-CO02 | C11: Secured command output, 12 outputs, 1-out-of-n check | D11: Siemens | E11: DO-8221 | F11: To confirm | G11: To confirm with supplier | H11: 2 | I11: pc | J11: =IF(Summary!$I$10="","",Summary!$I$10) | K11: =IF(OR(J11="",H11=""),"",H11*J11) | L11: 11 kV switchroom | M11: Breaker open and close AH1 to AH7. | N11: P1 | O11: DO8221
A12: P1.09 | B12: R1-DO01 | C12: Digital output, 8 relays, 24-220 V DC / 230 V AC | D12: Siemens | E12: DO-8212 | F12: 6MF2821-2AA00 | G12: Checked | H12: 1 | I12: pc | J12: =IF(Summary!$I$11="","",Summary!$I$11) | K12: =IF(OR(J12="",H12=""),"",H12*J12) | L12: 11 kV switchroom | M12: Alarm beacon, controller healthy. | N12: P1 | O12: DO8212
A13: P1.10 | B13: Row 2 interface | C13: I/O remote interface, electrical, 110-220 V DC | D13: Siemens | E13: CI-8532 | F13: 6MF2853-2AA00 | G13: Checked | H13: 1 | I13: pc | J13: =IF(Summary!$I$8="","",Summary!$I$8) | K13: =IF(OR(J13="",H13=""),"",H13*J13) | L13: 11 kV switchroom | N13: P1 | O13: CI8532
A14: P1.11 | B14: R2-DI01, R2-DI02 | C14: Digital input, 2 x 8 inputs, 110 V DC | D14: Siemens | E14: DI-8112 | F14: 6MF2811-2AA00 | G14: Checked | H14: 2 | I14: pc | J14: =IF(Summary!$I$9="","",Summary!$I$9) | K14: =IF(OR(J14="",H14=""),"",H14*J14) | L14: 11 kV switchroom | M14: Auxiliary TX, LV board, UPS, DC, E-stop, doors. | N14: P1 | O14: DI8112
A15: P1.12 | B15: R2-AI01 | C15: Analogue input, 4 x 4-20 mA | D15: Siemens | E15: AI-8320 | F15: 6MF2832-0AA00 | G15: Checked | H15: 1 | I15: pc | J15: =IF(Summary!$I$12="","",Summary!$I$12) | K15: =IF(OR(J15="",H15=""),"",H15*J15) | L15: 11 kV switchroom | M15: DC bus voltages. | N15: P1 | O15: AI8320
A16: P1.13 | B16: SW-CORE-A, SW-CORE-B | C16: Managed core switch, 8 x RJ45 + 4 x gigabit SFP | D16: Moxa | E16: EDS-G512E | F16: EDS-G512E-4GSFP | G16: From memory - confirm | H16: 2 | I16: pc | J16: =IF(Summary!$I$13="","",Summary!$I$13) | K16: =IF(OR(J16="",H16=""),"",H16*J16) | L16: 11 kV switchroom | N16: P1 | O16: CORE
A17: P1.14 | B17: Two per core switch | C17: SFP transceiver, gigabit, single-mode, LC | D17: Moxa | E17: SFP-1GLXLC | F17: SFP-1GLXLC | G17: From memory - confirm | H17: 4 | I17: pc | J17: =IF(Summary!$I$14="","",Summary!$I$14) | K17: =IF(OR(J17="",H17=""),"",H17*J17) | L17: 11 kV switchroom | M17: Ring ports and the core A-B link. | N17: P1 | O17: SFP
A18: P1.15 | B18: FW-01 | C18: Rugged firewall with VPN | D18: Fortinet | E18: FortiGate Rugged 60F | F18: FGR-60F | G18: From memory - confirm | H18: 1 | I18: pc | J18: =IF(Summary!$I$15="","",Summary!$I$15) | K18: =IF(OR(J18="",H18=""),"",H18*J18) | L18: 11 kV switchroom | M18: Second unit optional. | N18: P1 | O18: FW
A19: P1.16 | B19: GPS-01 | C19: GPS time server with antenna, cable and surge protector | D19: Meinberg | E19: LANTIME M300 | F19: M300/GPS | G19: From memory - confirm | H19: 1 | I19: set | J19: =IF(Summary!$I$16="","",Summary!$I$16) | K19: =IF(OR(J19="",H19=""),"",H19*J19) | L19: 11 kV switchroom | M19: Antenna on the switchroom roof; cable length to suit. | N19: P1 | O19: GPS
A20: P1.17 | B20: Cabinet 24 V | C20: 24 V DC power supply 20 A, input 85-275 V AC / 88-350 V DC | D20: Siemens | E20: SITOP PSU8200 24 V/20 A | F20: 6EP1336-3BA10 | G20: Checked | H20: 1 | I20: pc | J20: =IF(Summary!$I$17="","",Summary!$I$17) | K20: =IF(OR(J20="",H20=""),"",H20*J20) | L20: 11 kV switchroom | M20: Switches, firewall, gateway supply. Runs from the 110 V DC station battery. | N20: P1 | O20: PSU20
A21: P1.18 | B21: PM5560-AUX | C21: Power meter with Ethernet, Modbus TCP | D21: Schneider Electric | E21: PowerLogic PM5560 | F21: METSEPM5560 | G21: From memory - confirm | H21: 1 | I21: pc | J21: =IF(Summary!$I$18="","",Summary!$I$18) | K21: =IF(OR(J21="",H21=""),"",H21*J21) | L21: 11 kV switchroom | M21: Mounted in the auxiliary LV board. | N21: P1 | O21: PM5560
A22: P1.19 | B22: Fibre termination | C22: Fibre patch panel, 24 x LC, rack or DIN | D22: To suit | E22: - | F22: - | G22: TBC | H22: 1 | I22: pc | J22: =IF(Summary!$I$19="","",Summary!$I$19) | K22: =IF(OR(J22="",H22=""),"",H22*J22) | L22: 11 kV switchroom | N22: P1 | O22: FPP
A23: P1.20 | B23: SCADA cabinet | C23: SCADA cabinet 800 x 2000 x 800 mm, with plinth | D23: Rittal | E23: VX25 | F23: 8808.000 | G23: From memory - confirm | H23: 1 | I23: pc | J23: =IF(Summary!$I$20="","",Summary!$I$20) | K23: =IF(OR(J23="",H23=""),"",H23*J23) | L23: 11 kV switchroom | M23: Door contact wired to row 2. | N23: P1 | O23: VX25
A24: P1.21 | B24: SCADA cabinet | C24: Cabinet accessories: MCBs, terminals, surge protection, fans and thermostat, lighting, door switch, labels, wiring | D24: To suit | E24: - | F24: - | G24: TBC | H24: 1 | I24: lot | J24: =IF(Summary!$I$21="","",Summary!$I$21) | K24: =IF(OR(J24="",H24=""),"",H24*J24) | L24: 11 kV switchroom | N24: P1 | O24: ACC_C
B25: Subtotal P1 | K25: =SUM(K4:K24)
A27: P2 | B27: Control room (SCADA servers, operator and engineering stations)
A28: P2.01 | B28: SRV-A, SRV-B | C28: SCADA server, rack industrial PC, redundant power supplies and disks | D28: Siemens | E28: SIMATIC IPC647E | F28: Configured to order | G28: To confirm with supplier | H28: 2 | I28: pc | J28: =IF(Summary!$I$22="","",Summary!$I$22) | K28: =IF(OR(J28="",H28=""),"",H28*J28) | L28: Control room | M28: Server A active, B hot standby. | N28: P2 | O28: IPC
A29: P2.02 | B29: Server rack | C29: 19-inch rack 24U with rack console (monitor, keyboard, KVM) | D29: To suit | E29: - | F29: - | G29: TBC | H29: 1 | I29: set | J29: =IF(Summary!$I$23="","",Summary!$I$23) | K29: =IF(OR(J29="",H29=""),"",H29*J29) | L29: Control room | M29: Not in the Device List Rev 1; needed to house the rack servers and UPS. Confirm the room. | N29: P2 | O29: RACK
A30: P2.03 | B30: OWS-01 | C30: Operator workstation | D30: Dell | E30: OptiPlex 7000 series | F30: Configured to order | G30: To confirm with supplier | H30: 1 | I30: pc | J30: =IF(Summary!$I$24="","",Summary!$I$24) | K30: =IF(OR(J30="",H30=""),"",H30*J30) | L30: Control room | N30: P2 | O30: OWS
A31: P2.04 | B31: OWS-01 | C31: Monitor 24-inch, full HD | D31: Dell | E31: P2425H or equal | F31: To suit | G31: To confirm with supplier | H31: 2 | I31: pc | J31: =IF(Summary!$I$25="","",Summary!$I$25) | K31: =IF(OR(J31="",H31=""),"",H31*J31) | L31: Control room | M31: Two monitors. | N31: P2 | O31: MON
A32: P2.05 | B32: ENG-01 | C32: Engineering laptop, rugged | D32: Dell | E32: Latitude 5430 Rugged | F32: Configured to order | G32: To confirm with supplier | H32: 1 | I32: pc | J32: =IF(Summary!$I$26="","",Summary!$I$26) | K32: =IF(OR(J32="",H32=""),"",H32*J32) | L32: Control room | N32: P2 | O32: LAP
A33: P2.06 | B33: UPS-01 | C33: UPS 3000 VA online, rack, network card | D33: APC | E33: Smart-UPS SRT 3000 | F33: SRT3000RMXLI | G33: From memory - confirm | H33: 1 | I33: pc | J33: =IF(Summary!$I$27="","",Summary!$I$27) | K33: =IF(OR(J33="",H33=""),"",H33*J33) | L33: Control room | M33: SNMP to the SCADA. | N33: P2 | O33: UPS
A34: P2.07 | B34: UPS-01 | C34: External battery pack for the UPS (about 2 h runtime, to size) | D34: APC | E34: SRT96RMBP | F34: SRT96RMBP | G34: From memory - confirm | H34: 1 | I34: pc | J34: =IF(Summary!$I$28="","",Summary!$I$28) | K34: =IF(OR(J34="",H34=""),"",H34*J34) | L34: Control room | M34: Size for the runtime the client requires. | N34: P2 | O34: UPSB
A35: P2.08 | B35: ALM-01 | C35: Alarm sounder and beacon | D35: Pfannenberg | E35: PATROL | F35: Model to suit | G35: TBC | H35: 1 | I35: pc | J35: =IF(Summary!$I$29="","",Summary!$I$29) | K35: =IF(OR(J35="",H35=""),"",H35*J35) | L35: Control room | M35: Hardwired to row 1. | N35: P2 | O35: BEACON
B36: Subtotal P2 | K36: =SUM(K28:K35)
A38: P3 | B38: President station I/O panel (row 3, SW-PRS)
A39: P3.01 | B39: Row 3 interface | C39: I/O remote interface, optical, 110-220 V DC | D39: Siemens | E39: CI-8533 | F39: To confirm | G39: To confirm with supplier | H39: 1 | I39: pc | J39: =IF(Summary!$I$30="","",Summary!$I$30) | K39: =IF(OR(J39="",H39=""),"",H39*J39) | L39: President office transformer station | M39: Confirm fibre type and maximum length. | N39: P3 | O39: CI8533
A40: P3.02 | B40: R3-DI01 to R3-DI03 | C40: Digital input, 2 x 8 inputs, 110 V DC | D40: Siemens | E40: DI-8112 | F40: 6MF2811-2AA00 | G40: Checked | H40: 3 | I40: pc | J40: =IF(Summary!$I$9="","",Summary!$I$9) | K40: =IF(OR(J40="",H40=""),"",H40*J40) | L40: President office transformer station | M40: RMU, 630 kVA transformer, LVDB. | N40: P3 | O40: DI8112
A41: P3.03 | B41: R3-CO01 | C41: Secured command output, 12 outputs, 1-out-of-n check | D41: Siemens | E41: DO-8221 | F41: To confirm | G41: To confirm with supplier | H41: 1 | I41: pc | J41: =IF(Summary!$I$10="","",Summary!$I$10) | K41: =IF(OR(J41="",H41=""),"",H41*J41) | L41: President office transformer station | M41: RMU and LVDB commands. | N41: P3 | O41: DO8221
A42: P3.04 | B42: SW-PRS | C42: Managed field switch, 7 x RJ45 + 3 x gigabit combo/SFP | D42: Moxa | E42: EDS-510E | F42: EDS-510E-3GTXSFP | G42: From memory - confirm | H42: 1 | I42: pc | J42: =IF(Summary!$I$31="","",Summary!$I$31) | K42: =IF(OR(J42="",H42=""),"",H42*J42) | L42: President office transformer station | N42: P3 | O42: FSW
...

Sheet Summary
A1: Summary by order line | H1: Currency: | I1: [USD]
A2: Line | B2: Description | C2: Manufacturer | D2: Model | E2: Order no. | F2: Number status | G2: Unit | H2: Total qty | I2: Unit price | J2: Total price | K2: Used in | L2: Key
A3: 1 | B3: Processor module, SICAM A8000 | C3: Siemens | D3: CP-8050 | E3: 6MF2805-0AA00 | F3: Checked | G3: pc | H3: =IF(COUNTIFS('BOM by Panel'!$O$3:$O$137,L3,'BOM by Panel'!$H$3:$H$137,"<>")=0,"TBC",SUMIF('BOM by Panel'!$O$3:$O$137,L3,'BOM by Panel'!$H$3:$H$137)) | J3: =IF(OR(I3="",H3="TBC"),"",H3*I3) | K3: P1 | L3: CP8050
A4: 2 | B4: Power supply 110-220 V DC, 45 W | C4: Siemens | D4: PS-8642 | E4: 6MF2864-2AA00 | F4: Checked | G4: pc | H4: =IF(COUNTIFS('BOM by Panel'!$O$3:$O$137,L4,'BOM by Panel'!$H$3:$H$137,"<>")=0,"TBC",SUMIF('BOM by Panel'!$O$3:$O$137,L4,'BOM by Panel'!$H$3:$H$137)) | J4: =IF(OR(I4="",H4="TBC"),"",H4*I4) | K4: P1, SP | L4: PS8642
A5: 3 | B5: Ethernet interface, 5 x RJ45 | C5: Siemens | D5: CI-8520 | E5: 6MF2852-0AA00 | F5: Checked | G5: pc | H5: =IF(COUNTIFS('BOM by Panel'!$O$3:$O$137,L5,'BOM by Panel'!$H$3:$H$137,"<>")=0,"TBC",SUMIF('BOM by Panel'!$O$3:$O$137,L5,'BOM by Panel'!$H$3:$H$137)) | J5: =IF(OR(I5="",H5="TBC"),"",H5*I5) | K5: P1 | L5: CI8520
A6: 4 | B6: SICAM flash card, 2 GB | C6: Siemens | D6: SICAM flash card | E6: 6MF1213-1GA05-0AA0 | F6: Checked | G6: pc | H6: =IF(COUNTIFS('BOM by Panel'!$O$3:$O$137,L6,'BOM by Panel'!$H$3:$H$137,"<>")=0,"TBC",SUMIF('BOM by Panel'!$O$3:$O$137,L6,'BOM by Panel'!$H$3:$H$137)) | J6: =IF(OR(I6="",H6="TBC"),"",H6*I6) | K6: P1, SP | L6: FLASH
A7: 5 | B7: Protocol licences for one CP-8050: IEC 60870-5-104 server, Modbus TCP client, IEC 61850 client, hot standby function | C7: Siemens | D7: CP-8050 licences | E7: By quotation | F7: To confirm with supplier | G7: set | H7: =IF(COUNTIFS('BOM by Panel'!$O$3:$O$137,L7,'BOM by Panel'!$H$3:$H$137,"<>")=0,"TBC",SUMIF('BOM by Panel'!$O$3:$O$137,L7,'BOM by Panel'!$H$3:$H$137)) | J7: =IF(OR(I7="",H7="TBC"),"",H7*I7) | K7: P1 | L7: LIC
A8: 6 | B8: I/O remote interface, electrical, 110-220 V DC | C8: Siemens | D8: CI-8532 | E8: 6MF2853-2AA00 | F8: Checked | G8: pc | H8: =IF(COUNTIFS('BOM by Panel'!$O$3:$O$137,L8,'BOM by Panel'!$H$3:$H$137,"<>")=0,"TBC",SUMIF('BOM by Panel'!$O$3:$O$137,L8,'BOM by Panel'!$H$3:$H$137)) | J8: =IF(OR(I8="",H8="TBC"),"",H8*I8) | K8: P1 | L8: CI8532
A9: 7 | B9: Digital input, 2 x 8 inputs, 110 V DC | C9: Siemens | D9: DI-8112 | E9: 6MF2811-2AA00 | F9: Checked | G9: pc | H9: =IF(COUNTIFS('BOM by Panel'!$O$3:$O$137,L9,'BOM by Panel'!$H$3:$H$137,"<>")=0,"TBC",SUMIF('BOM by Panel'!$O$3:$O$137,L9,'BOM by Panel'!$H$3:$H$137)) | J9: =IF(OR(I9="",H9="TBC"),"",H9*I9) | K9: P1, P3, P4, P5, P6, SP | L9: DI8112
A10: 8 | B10: Secured command output, 12 outputs, 1-out-of-n check | C10: Siemens | D10: DO-8221 | E10: To confirm | F10: To confirm with supplier | G10: pc | H10: =IF(COUNTIFS('BOM by Panel'!$O$3:$O$137,L10,'BOM by Panel'!$H$3:$H$137,"<>")=0,"TBC",SUMIF('BOM by Panel'!$O$3:$O$137,L10,'BOM by Panel'!$H$3:$H$137)) | J10: =IF(OR(I10="",H10="TBC"),"",H10*I10) | K10: P1, P3, P4, SP | L10: DO8221
A11: 9 | B11: Digital output, 8 relays, 24-220 V DC / 230 V AC | C11: Siemens | D11: DO-8212 | E11: 6MF2821-2AA00 | F11: Checked | G11: pc | H11: =IF(COUNTIFS('BOM by Panel'!$O$3:$O$137,L11,'BOM by Panel'!$H$3:$H$137,"<>")=0,"TBC",SUMIF('BOM by Panel'!$O$3:$O$137,L11,'BOM by Panel'!$H$3:$H$137)) | J11: =IF(OR(I11="",H11="TBC"),"",H11*I11) | K11: P1 | L11: DO8212
A12: 10 | B12: Analogue input, 4 x 4-20 mA | C12: Siemens | D12: AI-8320 | E12: 6MF2832-0AA00 | F12: Checked | G12: pc | H12: =IF(COUNTIFS('BOM by Panel'!$O$3:$O$137,L12,'BOM by Panel'!$H$3:$H$137,"<>")=0,"TBC",SUMIF('BOM by Panel'!$O$3:$O$137,L12,'BOM by Panel'!$H$3:$H$137)) | J12: =IF(OR(I12="",H12="TBC"),"",H12*I12) | K12: P1, P6 | L12: AI8320
A13: 11 | B13: Managed core switch, 8 x RJ45 + 4 x gigabit SFP | C13: Moxa | D13: EDS-G512E | E13: EDS-G512E-4GSFP | F13: From memory - confirm | G13: pc | H13: =IF(COUNTIFS('BOM by Panel'!$O$3:$O$137,L13,'BOM by Panel'!$H$3:$H$137,"<>")=0,"TBC",SUMIF('BOM by Panel'!$O$3:$O$137,L13,'BOM by Panel'!$H$3:$H$137)) | J13: =IF(OR(I13="",H13="TBC"),"",H13*I13) | K13: P1 | L13: CORE
A14: 12 | B14: SFP transceiver, gigabit, single-mode, LC | C14: Moxa | D14: SFP-1GLXLC | E14: SFP-1GLXLC | F14: From memory - confirm | G14: pc | H14: =IF(COUNTIFS('BOM by Panel'!$O$3:$O$137,L14,'BOM by Panel'!$H$3:$H$137,"<>")=0,"TBC",SUMIF('BOM by Panel'!$O$3:$O$137,L14,'BOM by Panel'!$H$3:$H$137)) | J14: =IF(OR(I14="",H14="TBC"),"",H14*I14) | K14: P1, P3, P4, P5, P6, P7, SP | L14: SFP
... A50: 48 | B50: Firewall security services and support, 3 years | C50: Fortinet | D50: FortiGate Rugged 60F bundle | E50: By quotation | F50: To confirm with supplier | G50: lic | H50: =IF(COUNTIFS('BOM by Panel'!$O$3:$O$137,L50,'BOM by Panel'!$H$3:$H$137,"<>")=0,"TBC",SUMIF('BOM by Panel'!$O$3:$O$137,L50,'BOM by Panel'!$H$3:$H$137)) | J50: =IF(OR(I50="",H50="TBC"),"",H50*I50) | K50: S | L50: FWLIC
B51: Total materials | J51: =SUM(J3:J50)

Sheet IO Check
A1: I/O modules against the hardwired signals of the I/O list Rev 1
A2: Row | B2: Location | C2: Interface | D2: Modules | E2: Module count | F2: Channels | G2: Signals used | H2: Spare | I2: Spare % | J2: Remark
A3: 1 | B3: 11 kV switchroom | C3: CI-8532 | D3: DI-8112 x5, DO-8221 x2, DO-8212 x1 | E3: 8 | F3: 112 | G3: 87 | H3: =F3-G3 | I3: =H3/F3
A4: 2 | B4: SCADA cabinet | C4: CI-8532 | D4: DI-8112 x2, AI-8320 x1 | E4: 3 | F4: 36 | G4: 25 | H4: =F4-G4 | I4: =H4/F4
A5: 3 | B5: President station | C5: CI-8533 | D5: DI-8112 x3, DO-8221 x1 | E5: 4 | F5: 60 | G5: 43 | H5: =F5-G5 | I5: =H5/F5
A6: 4 | B6: PM station | C6: CI-8533 | D6: DI-8112 x3, DO-8221 x1 | E6: 4 | F6: 60 | G6: 43 | H6: =F6-G6 | I6: =H6/F6
A7: 5 | B7: BESS / inverter yard | C7: CI-8533 | D7: DI-8112 x2 | E7: 2 | F7: 32 | G7: 26 | H7: =F7-G7 | I7: =H7/F7 | J7: Below the 20 % target: add a third DI-8112 if more yard signals appear.
A8: 6 | B8: Generator area | C8: CI-8533 | D8: DI-8112 x2, AI-8320 x1 | E8: 3 | F8: 36 | G8: 20 | H8: =F8-G8 | I8: =H8/F8
B9: Total | E9: =SUM(E3:E8) | F9: =SUM(F3:F8) | G9: =SUM(G3:G8) | H9: =SUM(H3:H8) | I9: =H9/F9
B11: Check | D11: I/O modules in the BOM (rows 1 to 6, without spares) | E11: =SUMPRODUCT(('BOM by Panel'!$E$3:$E$137={"DI-8112","DO-8221","DO-8212","AI-8320"})*('BOM by Panel'!$N$3:$N$137<>"SP")*('BOM by Panel'!$H$3:$H$137)) | J11: =IF(E11=E9,"Matches the I/O list","Check the module quantities")

Sheet By Others
A1: Equipment the SCADA connects to but does not supply
A2: No. | B2: Equipment | C2: Make / model | D2: Supplied by | E2: What the SCADA needs from the supplier
A3: 1 | B3: PV string inverters NB01 to NB04 | C3: Sungrow SG350HX | D3: PV supplier | E3: Power line communication to the PLC box; nothing connects to the SCADA directly.
A4: 2 | B4: Power line communication box (PLC box) | C4: Sungrow, model TBC | D4: PV supplier | E4: Ethernet port and Modbus TCP register map; written list of settings the SCADA may write.
A5: 3 | B5: Embedded energy management system (EMS) | C5: TBC | D5: BESS / EMS supplier | E5: Ethernet port, Modbus TCP point table, heartbeat, written list of settings the SCADA may write.
A6: 4 | B6: Battery system 3,340 kWh | C6: Sungrow ST3340UX | D6: BESS supplier | E6: Read through the EMS. Fire, E-stop and door volt-free contacts at a terminal strip.
A7: 5 | B7: Generator controllers DG1, DG2 | C7: TBC | D7: Generator supplier | E7: Modbus TCP (or RTU, then add MGate-GEN); volt-free contacts for GCB, running, alarm, E-stop; 4-20 mA fuel level.
A8: 6 | B8: 11 kV protection relays AH1 to AH7 | C8: TBC | D8: Switchgear supplier | E8: Ethernet, two ports preferred; IEC 61850 or Modbus TCP documentation. Motorised breakers and auxiliary contacts.
A9: 7 | B9: Neutral earthing resistor panel AH8 | C9: TBC | D9: Switchgear supplier | E9: Auxiliary contacts: breaker, earth switch, gas, earth fault.
A10: 8 | B10: RMU protection relays | C10: ST260E | D10: RMU supplier | E10: RS485 port and Modbus map; motorised switches.
A11: 9 | B11: Transformers (inverter, DG step-up, auxiliary, 2 x 630 kVA) | C11: TBC | D11: Transformer supplier | E11: Alarm and trip contacts wired to a terminal box.
A12: 10 | B12: LV distribution boards and main breakers | C12: TBC | D12: Switchboard supplier | E12: Space and CT for the PM5560 meters; breaker auxiliary contacts; motorised LVDB incomers.
A13: 11 | B13: Fire detection and suppression panel | C13: TBC | D13: Fire system supplier | E13: Volt-free contacts per the I/O list; direct trip of the battery outside the SCADA.
A14: 12 | B14: UPS and 110 V DC station supplies | C14: TBC | D14: Electrical contractor | E14: 110 V DC for the controllers and I/O rows; alarm contacts; Modbus TCP or SNMP.
... A16: 14 | B16: RMU UPS 2 kVA | C16: TBC | D16: RMU supplier | E16: On battery and fault contacts.

Sheet Services
A1: Engineering and services (for the offer; not materials)
A2: No. | B2: Service | C2: Unit | D2: Qty | E2: Price
A3: 1 | B3: Engineering: controller configuration, interlocks, IP plan, SCADA database and screens | C3: lot | D3: 1
A4: 2 | B4: Panel build: SCADA cabinet and six field panels, with wiring and internal tests | C4: lot | D4: 1
A5: 3 | B5: Factory acceptance test with the client | C5: lot | D5: 1
A6: 4 | B6: Site installation supervision, termination and fibre splicing | C6: lot | D6: 1
A7: 5 | B7: Site acceptance and interface tests with the PV, BESS, generator and switchgear suppliers | C7: lot | D7: 1
A8: 6 | B8: Training: operators and administrators | C8: lot | D8: 1
A9: 7 | B9: Documentation: as-built drawings, manuals, configuration backups | C9: lot | D9: 1
A10: 8 | B10: Warranty and remote support, 2 years | C10: lot | D10: 1
B11: Total services | E11: =SUM(E3:E10)
