Workbook

Sheet Read Me
A1: Villa Somalia Hybrid Plant: SCADA Device and I/O List
A3: Project | B3: Solarization of Villa Somalia, Mogadishu. 1,516 kWp PV, 3,340 kWh BESS, 2 diesel generators, 11 kV switchboard, 2 office transformer stations.
A4: Status | B4: Rev 1, 15 Oct 2026: harmonised with the design report, the drawings and the HMI demonstration. For client submission as Attachment B.
A5: Controller | B5: Siemens SICAM A8000 CP-8050 as plant controller and gateway. The embedded EMS keeps dispatch of PV, battery and generators.
A6: SCADA | B6: Siemens SICAM SCC on two servers (active and hot standby), linked to the CP-8050 by IEC 60870-5-104.
A8: Sheets
A9: Device List | B9: Every device in the design: model, product or ordering number, quantity, location, interface and protocol to the CP-8050.
A10: Protocol Summary | B10: Device quantities per protocol, calculated from the Device List.
A11: IO List | B11: Every hardwired signal: tag, description, type, I/O row, module and channel, alarm level and who may operate it.
A12: Datasheets | B12: Register of every datasheet and software document for Attachment C, with where to download it and a Collected column.
A13: IO Rows | B13: Where each of the six I/O rows sits, its remote interface, link to the CP-8050 and the equipment wired to it.
A14: IO Summary | B14: Channels used and spare per I/O module, calculated from the IO List.
A15: Comms Points | B15: Typical signals read or written over communication links, per device type, with quantities. Replace with each vendor's point table.
A16: Comms Point List | B16: The Comms Points expanded to one row per signal, each with its own tag and alarm level, as used by the HMI.
A18: Number status key
A19: Checked | B19: Product number found on a supplier listing or a Siemens configuration document.
A20: From memory - confirm | B20: Ordering code from knowledge of the maker's catalogue; not checked online. Confirm with the distributor.
A21: To confirm with supplier | B21: Product exists but its number was not found. Take it from the supplier's quotation.
A22: Existing (drawings) | B22: Device already specified in drawing set VILLA_SOMALIA_05_10_2026.
A23: TBC | B23: Make or model unknown. Must come from the PV designer or the equipment supplier. Cells marked TBC are shaded yellow.
A25: Assumptions
A26: 1 | B26: Auxiliary control voltage is 110 V DC. This selects DI-8112, CI-8532, CI-8533 and PS-8642. For 24 V or 220 V DC see the variant note on the Device List.
A27: 2 | B27: 11 kV breakers, RMU switches and LVDB incomers are motorised and accept remote open and close.
A28: 3 | B28: The embedded EMS offers Modbus TCP. The PV inverter data reaches the CP-8050 from the power line communication box, as shown on the existing communication sheet.
A29: 4 | B29: Signal counts per device are typical values. They must be checked against the switchgear, RMU, transformer and fire panel terminal schedules.
A30: 5 | B30: Measurements (current, voltage, power, energy) come over communication from relays, meters and the EMS, not hardwired.
A31: 6 | B31: Spare capacity target is about 20% per I/O row.
A32: 7 | B32: Field signals are collected by the nearest I/O row: switchroom (rows 1, 2), office stations (rows 3, 4), BESS and inverter transformer yard (row 5), generator area (row 6). Remote rows 3 to 6 link to the CP-8050 by fibre. Actual cable distances are not known yet.
A34: Revision 1 changes
A35: 1 | B35: AH8: breaker open, closed, tripped, earth switch and gas pressure added (row 1). The 11 kV system is earthed only through AH8.
A36: 2 | B36: LV main breakers added: PV ACB 1250 A and BESS ACB 1000 A (row 5), DG step-up transformer LV ACB (row 6).
A37: 3 | B37: Combiner panels: trip of the four inverter AC MCCBs (row 5); battery combiner panel switch and fuse status through the EMS.
A38: 4 | B38: Auxiliary transformer XRNT-3A fuse blown (row 2); RMU UPS 2 kVA on battery and fault at both office stations (rows 3, 4).
A39: 5 | B39: 11 kV relays: trip circuit supervision (7), sensitive earth fault trip (6) and reverse power trip on AH1 added as communication points.
A40: 6 | B40: Totals: 244 hardwired signals and 456 communication points. Overall spare is 27%; row 5 drops to 19% (6 of 32 channels), just under the 20% target: add a third DI-8112 there if more yard signals appear.
A41: 7 | B41: Comms Point List sheet added. Devices D49 and D50 added to the Device List.

Sheet Device List
A1: ID | B1: Group | C1: Device | D1: Manufacturer | E1: Model | F1: Product / ordering no. | G1: Number status | H1: Qty | I1: Location | J1: Physical interface | K1: Protocol to CP-8050 | L1: Primary protocol | M1: Hardwired to I/O row | N1: Notes
A2: A. Plant equipment (existing or by others)
A3: D01 | B3: Plant | C3: PV string inverters NB01 to NB04 | D3: Sungrow | E3: SG350HX | F3: - | G3: Existing (drawings) | H3: 4 | I3: PV field | J3: AC power cable | K3: Power line communication to the PLC box | L3: Power line communication | M3: - | N3: Not connected to the CP-8050 directly.
A4: D02 | B4: Plant | C4: Power line communication box (PLC box) | D4: Sungrow | E4: TBC | F4: TBC | G4: TBC | H4: 1 | I4: Inverter MV station | J4: Ethernet RJ45 | K4: Modbus TCP (to confirm) | L4: Modbus TCP | M4: - | N4: Converts inverter data to Ethernet. Get model and point table from the PV designer.
A5: D03 | B5: Plant | C5: Embedded energy management system (EMS) | D5: TBC | E5: TBC | F5: TBC | G5: TBC | H5: 1 | I5: BESS / EMS area | J5: Ethernet RJ45 | K5: Modbus TCP (to confirm) | L5: Modbus TCP | M5: - | N5: Dispatches PV, battery and generators. Only the CP-8050 writes settings to it.
A6: D04 | B6: Plant | C6: Battery energy storage system, 3,340 kWh | D6: Sungrow | E6: ST3340UX | F6: - | G6: Existing (drawings) | H6: 1 | I6: BESS area | J6: Ethernet (via EMS) | K6: Through the EMS, Modbus TCP | L6: Modbus TCP | M6: - | N6: Confirm whether battery data is read through the EMS or directly. Battery combiner panel status read through the EMS if available (rev 1).
A7: D05 | B7: Plant | C7: Generator controllers DG1, DG2 | D7: TBC | E7: TBC | F7: TBC | G7: TBC | H7: 2 | I7: Generator area | J7: Ethernet or RS485 | K7: Modbus TCP, or Modbus RTU through a gateway | L7: Modbus TCP | M7: Row 6 | N7: Breaker status, alarm, E-stop, running and fuel level also hardwired to row 6.
A8: D06 | B8: Plant | C8: 11 kV protection relays, panels AH1 to AH7 | D8: TBC (switchgear supplier) | E8: TBC | F8: TBC | G8: TBC | H8: 7 | I8: 11 kV switchroom | J8: Ethernet, 2 ports preferred | K8: IEC 61850 MMS, or Modbus TCP | L8: IEC 61850 | M8: Row 1 | N8: Dual-connect to both core switches if the relay has two ports.
A9: D07 | B9: Plant | C9: Neutral earthing resistor panel AH8 | D9: TBC (switchgear supplier) | E9: - | F9: - | G9: TBC | H9: 1 | I9: 11 kV switchroom | J9: Dry contacts | K9: Hardwired | L9: Hardwired | M9: Row 1 | N9: Breaker position, trip, earth switch and gas pressure also wired to row 1 (rev 1).
A10: D08 | B10: Plant | C10: RMU protection relays | D10: Per RMU supplier | E10: ST260E | F10: - | G10: Existing (drawings) | H10: 2 | I10: President and PM stations | J10: RS485 | K10: Modbus RTU, converted by MGate gateway | L10: Modbus RTU | M10: Rows 3, 4 | N10: Confirm Modbus map with the RMU supplier.
A11: D09 | B11: Plant | C11: Transformers: inverter, DG step-up, 100 kVA auxiliary | D11: TBC | E11: - | F11: - | G11: TBC | H11: 3 | I11: Yard, generator area, switchroom | J11: Dry contacts | K11: Hardwired | L11: Hardwired | M11: Rows 5, 6, 2 | N11: Each wired to the nearest I/O row: inverter to row 5, DG step-up to row 6, auxiliary to row 2. Auxiliary transformer also has its XRNT-3A fuse striker wired to row 2 (rev 1).
A12: D10 | B12: Plant | C12: Transformers 630 kVA, President and PM stations | D12: TBC | E12: - | F12: - | G12: TBC | H12: 2 | I12: Office stations | J12: Dry contacts | K12: Hardwired | L12: Hardwired | M12: Rows 3, 4
A13: D11 | B13: Plant | C13: Low-voltage distribution boards, 10-way | D13: TBC | E13: - | F13: - | G13: TBC | H13: 2 | I13: Office stations | J13: Dry contacts + meter | K13: Hardwired; meter on Modbus TCP | L13: Hardwired | M13: Rows 3, 4
A14: D12 | B14: Plant | C14: Fire detection and suppression panel | D14: TBC | E14: TBC | F14: TBC | G14: TBC | H14: 1 | I14: BESS area | J14: Dry contacts | K14: Hardwired | L14: Hardwired | M14: Row 5 | N14: Also a direct hardwired trip to the battery, outside the SCADA.
A15: D13 | B15: Plant | C15: UPS and auxiliary DC supplies | D15: TBC | E15: TBC | F15: TBC | G15: TBC | H15: 1 | I15: 11 kV switchroom | J15: Ethernet or dry contacts | K15: Modbus TCP or SNMP, plus contacts | L15: Modbus TCP | M15: Row 2
A16: D14 | B16: Plant | C16: Weather station data logger | D16: Meteocontrol | E16: blue'Log XM with Multi I/O and Fieldbus Ext | F16: - | G16: Existing (drawings) | H16: 1 | I16: Inverter MV station | J16: Ethernet RJ45 | K16: Modbus TCP | L16: Modbus TCP | M16: - | N16: Collects the sensors below.
A17: D15 | B17: Plant | C17: Pyranometer | D17: Kipp & Zonen | E17: SMP12-A | F17: - | G17: Existing (drawings) | H17: 1 | I17: Weather mast | J17: RS485 to logger | K17: Through the blue'Log | L17: Through logger | M17: -
A18: D16 | B18: Plant | C18: Wind sensor | D18: Gill Instruments | E18: WindSonic RS485 | F18: - | G18: Existing (drawings) | H18: 1 | I18: Weather mast | J18: RS485 to logger | K18: Through the blue'Log | L18: Through logger | M18: -
A19: D17 | B19: Plant | C19: Ambient and module temperature sensors | D19: TBC | E19: - | F19: - | G19: Existing (drawings) | H19: 2 | I19: Weather mast / PV array | J19: Analogue to logger | K19: Through the blue'Log | L19: Through logger | M19: -
A20: D49 | B20: Plant | C20: LV main breakers: PV ACB 1250 A, BESS ACB 1000 A, DG step-up LV ACB; inverter AC MCCBs 400 A | D20: TBC (switchboard supplier) | E20: - | F20: - | G20: Existing (drawings) | H20: 3 | I20: Inverter MV station, BESS area, generator area | J20: Dry contacts | K20: Hardwired | L20: Hardwired | M20: Rows 5, 6 | N20: Added rev 1. Position and trip of each main breaker; trip of the four inverter MCCBs (row 5).
A21: D50 | B21: Plant | C21: RMU UPS 2 kVA, 220 V AC | D21: TBC (RMU supplier) | E21: - | F21: - | G21: Existing (drawings) | H21: 2 | I21: President and PM stations | J21: Dry contacts | K21: Hardwired | L21: Hardwired | M21: Rows 3, 4 | N21: Added rev 1. On battery and fault contacts.
A22: B. SICAM A8000 controller and I/O
A23: D18 | B23: Controller | C23: Processor module | D23: Siemens | E23: CP-8050 | F23: 6MF2805-0AA00 | G23: Checked | H23: 1 | I23: 11 kV switchroom | J23: 2 x RJ45 | K23: Gateway for all protocols | L23: IEC 60870-5-104 | M23: - | N23: To SCADA servers A and B.
A24: D19 | B24: Controller | C24: Power supply, 100 to 240 V DC/AC, 45 W | D24: Siemens | E24: PS-8642 | F24: 6MF2864-2AA00 | G24: Checked | H24: 2 | I24: 11 kV switchroom | J24: - | K24: - | L24: N/A | M24: - | N24: Two for redundancy; confirm the CP-8050 supports a second supply.
A25: D20 | B25: Controller | C25: Ethernet interface, 5 x RJ45 | D25: Siemens | E25: CI-8520 | F25: 6MF2852-0AA00 | G25: Checked | H25: 1 | I25: 11 kV switchroom | J25: 5 x RJ45 | K25: Separate ports per network zone | L25: N/A | M25: - | N25: Not a managed switch.
A26: D21 | B26: Controller | C26: Flash card, 2 GB | D26: Siemens | E26: SICAM flash card | F26: 6MF1213-1GA05-0AA0 | G26: Checked | H26: 1 | I26: 11 kV switchroom | J26: - | K26: - | L26: N/A | M26: -
A27: D22 | B27: I/O | C27: Digital input, 2 x 8 inputs | D27: Siemens | E27: DI-8112 | F27: 6MF2811-2AA00 | G27: Checked | H27: 17 | I27: Rows 1 to 6 | J27: Terminal | K27: SICAM I/O link | L27: SICAM I/O link | M27: Rows 1-6 | N27: Confirm DI-8112 is the 110 V DC variant. 24 V: DI-8110, 6MF2811-0AA00. 220 V: DI-8113, 6MF2811-3AA00.
A28: D23 | B28: I/O | C28: Secured command output, 12 outputs | D28: Siemens | E28: DO-8221 | F28: To confirm | G28: To confirm with supplier | H28: 4 | I28: Rows 1, 3, 4 | J28: Terminal | K28: SICAM I/O link | L28: SICAM I/O link | M28: Rows 1, 3, 4 | N28: Breaker open and close with 1-out-of-n check.
A29: D24 | B29: I/O | C29: Digital output, 8 relays, 24-220 V DC / 230 V AC | D29: Siemens | E29: DO-8212 | F29: 6MF2821-2AA00 | G29: Checked | H29: 1 | I29: Row 1 | J29: Terminal | K29: SICAM I/O link | L29: SICAM I/O link | M29: Row 1 | N29: Alarm beacon and controller healthy output.
A30: D25 | B30: I/O | C30: Analogue input, 4 x +/-20 mA or +/-10 V | D30: Siemens | E30: AI-8320 | F30: 6MF2832-0AA00 | G30: Checked | H30: 2 | I30: Rows 2, 6 | J30: Terminal | K30: SICAM I/O link | L30: SICAM I/O link | M30: Rows 2, 6 | N30: Row 2: DC bus voltages. Row 6: generator fuel levels.
A31: D26 | B31: I/O | C31: I/O remote interface, electrical, 110-220 V DC | D31: Siemens | E31: CI-8532 | F31: 6MF2853-2AA00 | G31: Checked | H31: 1 | I31: Row 2 | J31: Copper | K31: SICAM I/O link | L31: SICAM I/O link | M31: Row 2 | N31: 24 V variant: CI-8530, 6MF2853-0AA00.
A32: D27 | B32: I/O | C32: I/O remote interface, optical, 110-220 V DC | D32: Siemens | E32: CI-8533 | F32: To confirm | G32: To confirm with supplier | H32: 4 | I32: Rows 3 to 6 | J32: Fibre | K32: SICAM I/O link, optical | L32: SICAM I/O link | M32: Rows 3-6 | N32: One per remote row: President, Prime Minister, BESS yard, generator area. Confirm fibre type and maximum length. Within about 100 m of the switchroom, CI-8532 on copper may be used instead. 24 V variant: CI-8531.
A33: D28 | B33: I/O | C33: Protocol licences: IEC 104, Modbus TCP client, IEC 61850 client | D33: Siemens | E33: For CP-8050 | F33: By quotation | G33: To confirm with supplier | H33: 1 | I33: - | J33: - | K33: - | L33: N/A | M33: -
A34: C. Network, time and security
A35: D29 | B35: Network | C35: Core switch, managed, gigabit, SFP | D35: Moxa | E35: EDS-G512E | F35: EDS-G512E-4GSFP | G35: From memory - confirm | H35: 2 | I35: 11 kV switchroom | J35: RJ45 + SFP | K35: Ethernet, VLANs, ring | L35: N/A | M35: - | N35: Core switch A and B.
A36: D30 | B36: Network | C36: Field and station switch, managed, SFP | D36: Moxa | E36: EDS-510E | F36: EDS-510E-3GTXSFP | G36: From memory - confirm | H36: 5 | I36: MV station, BESS, generators, 2 office stations | J36: RJ45 + SFP | K36: Ethernet, ring | L36: N/A | M36: - | N36: Replaces the unmanaged switch on the existing sheet.
A37: D31 | B37: Network | C37: Fibre transceiver, single-mode, gigabit | D37: Moxa | E37: SFP-1GLXLC | F37: SFP-1GLXLC | G37: From memory - confirm | H37: 14 | I37: All switches | J37: LC fibre | K37: - | L37: N/A | M37: - | N37: 7-switch ring, 2 per link.
A38: D32 | B38: Network | C38: Serial to Ethernet gateway | D38: Moxa | E38: MGate MB3170 | F38: MB3170 | G38: From memory - confirm | H38: 2 | I38: Office stations | J38: RS485 + RJ45 | K38: Modbus RTU to Modbus TCP | L38: Modbus TCP | M38: - | N38: Add one more if the generator controllers are RS485 only.
A39: D33 | B39: Network | C39: Firewall with VPN | D39: Fortinet | E39: FortiGate Rugged 60F | F39: FGR-60F | G39: From memory - confirm | H39: 1 | I39: 11 kV switchroom | J39: RJ45 | K39: VPN, off by default | L39: N/A | M39: - | N39: Second unit optional.
A40: D34 | B40: Network | C40: GPS time server with antenna | D40: Meinberg | E40: LANTIME M300 | F40: M300/GPS | G40: From memory - confirm | H40: 1 | I40: 11 kV switchroom | J40: RJ45 | K40: NTP | L40: NTP | M40: -
...

Sheet Protocol Summary
A1: Primary protocol | B1: Where used | C1: Device lines | D1: Device quantity
A2: IEC 60870-5-104 | B2: CP-8050 to SCADA servers A and B | C2: =COUNTIF('Device List'!$L$2:$L$56,A2) | D2: =SUMIF('Device List'!$L$2:$L$56,A2,'Device List'!$H$2:$H$56)
A3: IEC 61850 | B3: 11 kV protection relays (Modbus TCP if not supported) | C3: =COUNTIF('Device List'!$L$2:$L$56,A3) | D3: =SUMIF('Device List'!$L$2:$L$56,A3,'Device List'!$H$2:$H$56)
A4: Modbus TCP | B4: PLC box, EMS, battery via EMS, generator controllers, power meters, weather logger, UPS, gateways | C4: =COUNTIF('Device List'!$L$2:$L$56,A4) | D4: =SUMIF('Device List'!$L$2:$L$56,A4,'Device List'!$H$2:$H$56)
A5: Modbus RTU | B5: RMU relays ST260E, through MGate gateways | C5: =COUNTIF('Device List'!$L$2:$L$56,A5) | D5: =SUMIF('Device List'!$L$2:$L$56,A5,'Device List'!$H$2:$H$56)
A6: SICAM I/O link | B6: CP-8050 to I/O modules and remote rows (Siemens proprietary) | C6: =COUNTIF('Device List'!$L$2:$L$56,A6) | D6: =SUMIF('Device List'!$L$2:$L$56,A6,'Device List'!$H$2:$H$56)
A7: Hardwired | B7: Status contacts, alarms and commands wired to I/O modules | C7: =COUNTIF('Device List'!$L$2:$L$56,A7) | D7: =SUMIF('Device List'!$L$2:$L$56,A7,'Device List'!$H$2:$H$56)
A8: Power line communication | B8: PV inverters to the PLC box over the AC cables | C8: =COUNTIF('Device List'!$L$2:$L$56,A8) | D8: =SUMIF('Device List'!$L$2:$L$56,A8,'Device List'!$H$2:$H$56)
A9: NTP | B9: Time synchronisation from the GPS time server | C9: =COUNTIF('Device List'!$L$2:$L$56,A9) | D9: =SUMIF('Device List'!$L$2:$L$56,A9,'Device List'!$H$2:$H$56)
A10: Through logger | B10: Weather sensors to the blue'Log | C10: =COUNTIF('Device List'!$L$2:$L$56,A10) | D10: =SUMIF('Device List'!$L$2:$L$56,A10,'Device List'!$H$2:$H$56)
A12: Supervision protocols: SNMP v3 and syslog from switches, firewall and time server to the SCADA servers.

Sheet IO List
A1: Tag | B1: Description | C1: Equipment | D1: Location | E1: Type | F1: I/O row | G1: Module | H1: Module type | I1: Channel | J1: Normal state / range | K1: Alarm level | L1: Operated by | M1: Notes
A2: AH1-CB-OPEN | B2: Circuit breaker open | C2: 11 kV panel AH1, Generator incomer | D2: 11 kV switchroom | E2: DI | F2: 1 | G2: R1-DI01 | H2: DI-8112 | I2: 1 | J2: Status | K2: Status | L2: -
A3: AH1-CB-CLSD | B3: Circuit breaker closed | C3: 11 kV panel AH1, Generator incomer | D3: 11 kV switchroom | E3: DI | F3: 1 | G3: R1-DI01 | H3: DI-8112 | I3: 2 | J3: Status | K3: Status | L3: -
A4: AH1-CB-TRIP | B4: Circuit breaker tripped by protection | C4: 11 kV panel AH1, Generator incomer | D4: 11 kV switchroom | E4: DI | F4: 1 | G4: R1-DI01 | H4: DI-8112 | I4: 3 | J4: Normally open | K4: 1 | L4: -
A5: AH1-ES-CLSD | B5: Earth switch closed | C5: 11 kV panel AH1, Generator incomer | D5: 11 kV switchroom | E5: DI | F5: 1 | G5: R1-DI01 | H5: DI-8112 | I5: 4 | J5: Status | K5: Status | L5: - | M5: Interlock: blocks remote close
A6: AH1-LR-REM | B6: Local/remote switch in remote | C6: 11 kV panel AH1, Generator incomer | D6: 11 kV switchroom | E6: DI | F6: 1 | G6: R1-DI01 | H6: DI-8112 | I6: 5 | J6: Status | K6: Status | L6: - | M6: Interlock: remote commands only in remote
A7: AH1-SPR-CHG | B7: Closing spring charged | C7: 11 kV panel AH1, Generator incomer | D7: 11 kV switchroom | E7: DI | F7: 1 | G7: R1-DI01 | H7: DI-8112 | I7: 6 | J7: Normally closed | K7: 3 | L7: -
A8: AH1-GAS-LOW | B8: Gas pressure low | C8: 11 kV panel AH1, Generator incomer | D8: 11 kV switchroom | E8: DI | F8: 1 | G8: R1-DI01 | H8: DI-8112 | I8: 7 | J8: Normally open | K8: 2 | L8: -
A9: AH1-RLY-OK | B9: Protection relay healthy | C9: 11 kV panel AH1, Generator incomer | D9: 11 kV switchroom | E9: DI | F9: 1 | G9: R1-DI01 | H9: DI-8112 | I9: 8 | J9: Normally closed | K9: 2 | L9: -
A10: AH1-AUX-OK | B10: Control supply healthy | C10: 11 kV panel AH1, Generator incomer | D10: 11 kV switchroom | E10: DI | F10: 1 | G10: R1-DI01 | H10: DI-8112 | I10: 9 | J10: Normally closed | K10: 2 | L10: -
A11: AH2-CB-OPEN | B11: Circuit breaker open | C11: 11 kV panel AH2, PV incomer | D11: 11 kV switchroom | E11: DI | F11: 1 | G11: R1-DI01 | H11: DI-8112 | I11: 10 | J11: Status | K11: Status | L11: -
A12: AH2-CB-CLSD | B12: Circuit breaker closed | C12: 11 kV panel AH2, PV incomer | D12: 11 kV switchroom | E12: DI | F12: 1 | G12: R1-DI01 | H12: DI-8112 | I12: 11 | J12: Status | K12: Status | L12: -
A13: AH2-CB-TRIP | B13: Circuit breaker tripped by protection | C13: 11 kV panel AH2, PV incomer | D13: 11 kV switchroom | E13: DI | F13: 1 | G13: R1-DI01 | H13: DI-8112 | I13: 12 | J13: Normally open | K13: 1 | L13: -
A14: AH2-ES-CLSD | B14: Earth switch closed | C14: 11 kV panel AH2, PV incomer | D14: 11 kV switchroom | E14: DI | F14: 1 | G14: R1-DI01 | H14: DI-8112 | I14: 13 | J14: Status | K14: Status | L14: - | M14: Interlock: blocks remote close
A15: AH2-LR-REM | B15: Local/remote switch in remote | C15: 11 kV panel AH2, PV incomer | D15: 11 kV switchroom | E15: DI | F15: 1 | G15: R1-DI01 | H15: DI-8112 | I15: 14 | J15: Status | K15: Status | L15: - | M15: Interlock: remote commands only in remote
A16: AH2-SPR-CHG | B16: Closing spring charged | C16: 11 kV panel AH2, PV incomer | D16: 11 kV switchroom | E16: DI | F16: 1 | G16: R1-DI01 | H16: DI-8112 | I16: 15 | J16: Normally closed | K16: 3 | L16: -
A17: AH2-GAS-LOW | B17: Gas pressure low | C17: 11 kV panel AH2, PV incomer | D17: 11 kV switchroom | E17: DI | F17: 1 | G17: R1-DI01 | H17: DI-8112 | I17: 16 | J17: Normally open | K17: 2 | L17: -
A18: AH2-RLY-OK | B18: Protection relay healthy | C18: 11 kV panel AH2, PV incomer | D18: 11 kV switchroom | E18: DI | F18: 1 | G18: R1-DI02 | H18: DI-8112 | I18: 1 | J18: Normally closed | K18: 2 | L18: -
A19: AH2-AUX-OK | B19: Control supply healthy | C19: 11 kV panel AH2, PV incomer | D19: 11 kV switchroom | E19: DI | F19: 1 | G19: R1-DI02 | H19: DI-8112 | I19: 2 | J19: Normally closed | K19: 2 | L19: -
A20: AH3-CB-OPEN | B20: Circuit breaker open | C20: 11 kV panel AH3, BESS incomer | D20: 11 kV switchroom | E20: DI | F20: 1 | G20: R1-DI02 | H20: DI-8112 | I20: 3 | J20: Status | K20: Status | L20: -
A21: AH3-CB-CLSD | B21: Circuit breaker closed | C21: 11 kV panel AH3, BESS incomer | D21: 11 kV switchroom | E21: DI | F21: 1 | G21: R1-DI02 | H21: DI-8112 | I21: 4 | J21: Status | K21: Status | L21: -
A22: AH3-CB-TRIP | B22: Circuit breaker tripped by protection | C22: 11 kV panel AH3, BESS incomer | D22: 11 kV switchroom | E22: DI | F22: 1 | G22: R1-DI02 | H22: DI-8112 | I22: 5 | J22: Normally open | K22: 1 | L22: -
A23: AH3-ES-CLSD | B23: Earth switch closed | C23: 11 kV panel AH3, BESS incomer | D23: 11 kV switchroom | E23: DI | F23: 1 | G23: R1-DI02 | H23: DI-8112 | I23: 6 | J23: Status | K23: Status | L23: - | M23: Interlock: blocks remote close
A24: AH3-LR-REM | B24: Local/remote switch in remote | C24: 11 kV panel AH3, BESS incomer | D24: 11 kV switchroom | E24: DI | F24: 1 | G24: R1-DI02 | H24: DI-8112 | I24: 7 | J24: Status | K24: Status | L24: - | M24: Interlock: remote commands only in remote
A25: AH3-SPR-CHG | B25: Closing spring charged | C25: 11 kV panel AH3, BESS incomer | D25: 11 kV switchroom | E25: DI | F25: 1 | G25: R1-DI02 | H25: DI-8112 | I25: 8 | J25: Normally closed | K25: 3 | L25: -
A26: AH3-GAS-LOW | B26: Gas pressure low | C26: 11 kV panel AH3, BESS incomer | D26: 11 kV switchroom | E26: DI | F26: 1 | G26: R1-DI02 | H26: DI-8112 | I26: 9 | J26: Normally open | K26: 2 | L26: -
A27: AH3-RLY-OK | B27: Protection relay healthy | C27: 11 kV panel AH3, BESS incomer | D27: 11 kV switchroom | E27: DI | F27: 1 | G27: R1-DI02 | H27: DI-8112 | I27: 10 | J27: Normally closed | K27: 2 | L27: -
A28: AH3-AUX-OK | B28: Control supply healthy | C28: 11 kV panel AH3, BESS incomer | D28: 11 kV switchroom | E28: DI | F28: 1 | G28: R1-DI02 | H28: DI-8112 | I28: 11 | J28: Normally closed | K28: 2 | L28: -
A29: AH4-CB-OPEN | B29: Circuit breaker open | C29: 11 kV panel AH4, President feeder | D29: 11 kV switchroom | E29: DI | F29: 1 | G29: R1-DI02 | H29: DI-8112 | I29: 12 | J29: Status | K29: Status | L29: -
A30: AH4-CB-CLSD | B30: Circuit breaker closed | C30: 11 kV panel AH4, President feeder | D30: 11 kV switchroom | E30: DI | F30: 1 | G30: R1-DI02 | H30: DI-8112 | I30: 13 | J30: Status | K30: Status | L30: -
A31: AH4-CB-TRIP | B31: Circuit breaker tripped by protection | C31: 11 kV panel AH4, President feeder | D31: 11 kV switchroom | E31: DI | F31: 1 | G31: R1-DI02 | H31: DI-8112 | I31: 14 | J31: Normally open | K31: 1 | L31: -
A32: AH4-ES-CLSD | B32: Earth switch closed | C32: 11 kV panel AH4, President feeder | D32: 11 kV switchroom | E32: DI | F32: 1 | G32: R1-DI02 | H32: DI-8112 | I32: 15 | J32: Status | K32: Status | L32: - | M32: Interlock: blocks remote close
A33: AH4-LR-REM | B33: Local/remote switch in remote | C33: 11 kV panel AH4, President feeder | D33: 11 kV switchroom | E33: DI | F33: 1 | G33: R1-DI02 | H33: DI-8112 | I33: 16 | J33: Status | K33: Status | L33: - | M33: Interlock: remote commands only in remote
A34: AH4-SPR-CHG | B34: Closing spring charged | C34: 11 kV panel AH4, President feeder | D34: 11 kV switchroom | E34: DI | F34: 1 | G34: R1-DI03 | H34: DI-8112 | I34: 1 | J34: Normally closed | K34: 3 | L34: -
A35: AH4-GAS-LOW | B35: Gas pressure low | C35: 11 kV panel AH4, President feeder | D35: 11 kV switchroom | E35: DI | F35: 1 | G35: R1-DI03 | H35: DI-8112 | I35: 2 | J35: Normally open | K35: 2 | L35: -
A36: AH4-RLY-OK | B36: Protection relay healthy | C36: 11 kV panel AH4, President feeder | D36: 11 kV switchroom | E36: DI | F36: 1 | G36: R1-DI03 | H36: DI-8112 | I36: 3 | J36: Normally closed | K36: 2 | L36: -
A37: AH4-AUX-OK | B37: Control supply healthy | C37: 11 kV panel AH4, President feeder | D37: 11 kV switchroom | E37: DI | F37: 1 | G37: R1-DI03 | H37: DI-8112 | I37: 4 | J37: Normally closed | K37: 2 | L37: -
A38: AH5-CB-OPEN | B38: Circuit breaker open | C38: 11 kV panel AH5, Auxiliary transformer feeder | D38: 11 kV switchroom | E38: DI | F38: 1 | G38: R1-DI03 | H38: DI-8112 | I38: 5 | J38: Status | K38: Status | L38: -
A39: AH5-CB-CLSD | B39: Circuit breaker closed | C39: 11 kV panel AH5, Auxiliary transformer feeder | D39: 11 kV switchroom | E39: DI | F39: 1 | G39: R1-DI03 | H39: DI-8112 | I39: 6 | J39: Status | K39: Status | L39: -
A40: AH5-CB-TRIP | B40: Circuit breaker tripped by protection | C40: 11 kV panel AH5, Auxiliary transformer feeder | D40: 11 kV switchroom | E40: DI | F40: 1 | G40: R1-DI03 | H40: DI-8112 | I40: 7 | J40: Normally open | K40: 1 | L40: -
...

Sheet IO Summary
A1: I/O row | B1: Location | C1: Module | D1: Module type | E1: Channels | F1: Used | G1: Spare | H1: Spare %
A2: 1 | B2: 11 kV switchroom (local) | C2: R1-DI01 | D2: DI-8112 | E2: 16 | F2: =COUNTIF('IO List'!$G$2:$G$245,C2) | G2: =E2-F2 | H2: =IF(E2=0,0,G2/E2)
A3: 1 | B3: 11 kV switchroom (local) | C3: R1-DI02 | D3: DI-8112 | E3: 16 | F3: =COUNTIF('IO List'!$G$2:$G$245,C3) | G3: =E3-F3 | H3: =IF(E3=0,0,G3/E3)
A4: 1 | B4: 11 kV switchroom (local) | C4: R1-DI03 | D4: DI-8112 | E4: 16 | F4: =COUNTIF('IO List'!$G$2:$G$245,C4) | G4: =E4-F4 | H4: =IF(E4=0,0,G4/E4)
A5: 1 | B5: 11 kV switchroom (local) | C5: R1-DI04 | D5: DI-8112 | E5: 16 | F5: =COUNTIF('IO List'!$G$2:$G$245,C5) | G5: =E5-F5 | H5: =IF(E5=0,0,G5/E5)
A6: 1 | B6: 11 kV switchroom (local) | C6: R1-DI05 | D6: DI-8112 | E6: 16 | F6: =COUNTIF('IO List'!$G$2:$G$245,C6) | G6: =E6-F6 | H6: =IF(E6=0,0,G6/E6)
A7: 1 | B7: 11 kV switchroom (local) | C7: R1-CO01 | D7: DO-8221 | E7: 12 | F7: =COUNTIF('IO List'!$G$2:$G$245,C7) | G7: =E7-F7 | H7: =IF(E7=0,0,G7/E7)
A8: 1 | B8: 11 kV switchroom (local) | C8: R1-CO02 | D8: DO-8221 | E8: 12 | F8: =COUNTIF('IO List'!$G$2:$G$245,C8) | G8: =E8-F8 | H8: =IF(E8=0,0,G8/E8)
A9: 1 | B9: 11 kV switchroom (local) | C9: R1-DO01 | D9: DO-8212 | E9: 8 | F9: =COUNTIF('IO List'!$G$2:$G$245,C9) | G9: =E9-F9 | H9: =IF(E9=0,0,G9/E9)
A10: 2 | B10: 11 kV switchroom (CI-8532) | C10: R2-DI01 | D10: DI-8112 | E10: 16 | F10: =COUNTIF('IO List'!$G$2:$G$245,C10) | G10: =E10-F10 | H10: =IF(E10=0,0,G10/E10)
A11: 2 | B11: 11 kV switchroom (CI-8532) | C11: R2-DI02 | D11: DI-8112 | E11: 16 | F11: =COUNTIF('IO List'!$G$2:$G$245,C11) | G11: =E11-F11 | H11: =IF(E11=0,0,G11/E11)
A12: 2 | B12: 11 kV switchroom (CI-8532) | C12: R2-AI01 | D12: AI-8320 | E12: 4 | F12: =COUNTIF('IO List'!$G$2:$G$245,C12) | G12: =E12-F12 | H12: =IF(E12=0,0,G12/E12)
A13: 3 | B13: President station (CI-8533) | C13: R3-DI01 | D13: DI-8112 | E13: 16 | F13: =COUNTIF('IO List'!$G$2:$G$245,C13) | G13: =E13-F13 | H13: =IF(E13=0,0,G13/E13)
... A25: 6 | B25: Generator area (CI-8533) | C25: R6-AI01 | D25: AI-8320 | E25: 4 | F25: =COUNTIF('IO List'!$G$2:$G$245,C25) | G25: =E25-F25 | H25: =IF(E25=0,0,G25/E25)
A27: Totals by module type
A28: Module type | B28: Description | C28: Modules | D28: Channels | E28: Used | F28: Spare | G28: Spare %
A29: DI-8112 | B29: Digital input, 16 | C29: =COUNTIF($D$2:$D$25,A29) | D29: =SUMIF($D$2:$D$25,A29,$E$2:$E$25) | E29: =SUMIF($D$2:$D$25,A29,$F$2:$F$25) | F29: =D29-E29 | G29: =IF(D29=0,0,F29/D29)
A30: DO-8221 | B30: Secured command output, 12 | C30: =COUNTIF($D$2:$D$25,A30) | D30: =SUMIF($D$2:$D$25,A30,$E$2:$E$25) | E30: =SUMIF($D$2:$D$25,A30,$F$2:$F$25) | F30: =D30-E30 | G30: =IF(D30=0,0,F30/D30)
A31: DO-8212 | B31: Relay output, 8 | C31: =COUNTIF($D$2:$D$25,A31) | D31: =SUMIF($D$2:$D$25,A31,$E$2:$E$25) | E31: =SUMIF($D$2:$D$25,A31,$F$2:$F$25) | F31: =D31-E31 | G31: =IF(D31=0,0,F31/D31)
A32: AI-8320 | B32: Analogue input, 4 | C32: =COUNTIF($D$2:$D$25,A32) | D32: =SUMIF($D$2:$D$25,A32,$E$2:$E$25) | E32: =SUMIF($D$2:$D$25,A32,$F$2:$F$25) | F32: =D32-E32 | G32: =IF(D32=0,0,F32/D32)
A33: Total | C33: =SUM(C29:C32) | D33: =SUM(D29:D32) | E33: =SUM(E29:E32) | F33: =SUM(F29:F32) | G33: =IF(D33=0,0,F33/D33)
A35: Hardwired signals by type
A36: Type | B36: Meaning | C36: Signals
A37: DI | B37: Digital input (status, alarm) | C37: =COUNTIF('IO List'!$E$2:$E$245,A37)
A38: DO | B38: Digital output (command) | C38: =COUNTIF('IO List'!$E$2:$E$245,A38)
A39: AI | B39: Analogue input (4-20 mA) | C39: =COUNTIF('IO List'!$E$2:$E$245,A39)
A40: Total | C40: =SUM(C37:C39)

Sheet IO Rows
A1: I/O row | B1: Location | C1: Remote interface | D1: Product number | E1: Link to CP-8050 | F1: Equipment wired to this row | G1: I/O modules | H1: Hardwired signals | I1: Spare channels
A2: 1 | B2: 11 kV switchroom, beside the CP-8050 | C2: None (local row) | D2: - | E2: Backplane, no cable | F2: 11 kV panels AH1 to AH8, alarm beacon, controller watchdog | G2: =COUNTIF('IO Summary'!$A$2:$A$25,A2) | H2: =COUNTIF('IO List'!$F$2:$F$245,A2) | I2: =SUMIF('IO Summary'!$A$2:$A$25,A2,'IO Summary'!$G$2:$G$25)
A3: 2 | B3: 11 kV switchroom, SCADA cabinet | C3: CI-8532 (electrical) | D3: 6MF2853-2AA00 | E3: Copper, inside the cabinet | F3: Auxiliary transformer, auxiliary LV board, UPS, DC supplies, switchroom E-stop and doors | G3: =COUNTIF('IO Summary'!$A$2:$A$25,A3) | H3: =COUNTIF('IO List'!$F$2:$F$245,A3) | I3: =SUMIF('IO Summary'!$A$2:$A$25,A3,'IO Summary'!$G$2:$G$25)
A4: 3 | B4: President office transformer station | C4: CI-8533 (optical) | D4: To confirm | E4: Fibre pair, laid with the 11 kV cable | F4: RMU, 630 kVA transformer, LVDB | G4: =COUNTIF('IO Summary'!$A$2:$A$25,A4) | H4: =COUNTIF('IO List'!$F$2:$F$245,A4) | I4: =SUMIF('IO Summary'!$A$2:$A$25,A4,'IO Summary'!$G$2:$G$25)
A5: 4 | B5: Prime Minister office transformer station | C5: CI-8533 (optical) | D5: To confirm | E5: Fibre pair, laid with the 11 kV cable | F5: RMU, 630 kVA transformer, LVDB | G5: =COUNTIF('IO Summary'!$A$2:$A$25,A5) | H5: =COUNTIF('IO List'!$F$2:$F$245,A5) | I5: =SUMIF('IO Summary'!$A$2:$A$25,A5,'IO Summary'!$G$2:$G$25)
A6: 5 | B6: BESS and inverter transformer yard | C6: CI-8533 (optical) | D6: To confirm | E6: Spare fibre pair in the field switch 2 cable | F6: Inverter transformer, battery fire panel, BESS E-stop and door, panel supervision | G6: =COUNTIF('IO Summary'!$A$2:$A$25,A6) | H6: =COUNTIF('IO List'!$F$2:$F$245,A6) | I6: =SUMIF('IO Summary'!$A$2:$A$25,A6,'IO Summary'!$G$2:$G$25)
A7: 6 | B7: Generator area | C7: CI-8533 (optical) | D7: To confirm | E7: Spare fibre pair in the field switch 3 cable | F7: DG1 and DG2 status and fuel level, DG step-up transformer, panel supervision | G7: =COUNTIF('IO Summary'!$A$2:$A$25,A7) | H7: =COUNTIF('IO List'!$F$2:$F$245,A7) | I7: =SUMIF('IO Summary'!$A$2:$A$25,A7,'IO Summary'!$G$2:$G$25)
A8: Total | G8: =SUM(G2:G7) | H8: =SUM(H2:H7) | I8: =SUM(I2:I7)
A10: Each remote row is a small panel near its equipment. Field contacts are wired a short distance to that panel; one link carries all signals to the CP-8050.
A11: Rows within about 100 m of the switchroom may use CI-8532 on copper instead of CI-8533 on fibre. Fibre is preferred between buildings for surge and earth-potential immunity.
A12: Confirm with Siemens: fibre type and maximum length for CI-8533, and whether the remote link can share a fibre cable with the plant network on separate cores.
A13: The CP-8050 accepts up to 16 I/O rows of 8 modules, so the design uses 6 of 16 rows.

Sheet Comms Points
A1: Device | B1: Source / protocol | C1: Point | D1: Direction | E1: Data type | F1: Unit | G1: Devices | H1: Points each | I1: Total points | J1: Operated by | K1: Notes
A2: PV inverter NB01 to NB04 | B2: PLC box, Modbus TCP | C2: Active power | D2: Read | E2: Measured | F2: kW | G2: 4 | H2: 1 | I2: =G2*H2 | J2: -
A3: PV inverter NB01 to NB04 | B3: PLC box, Modbus TCP | C3: Reactive power | D3: Read | E3: Measured | F3: kvar | G3: 4 | H3: 1 | I3: =G3*H3 | J3: -
A4: PV inverter NB01 to NB04 | B4: PLC box, Modbus TCP | C4: AC voltage L1, L2, L3 (3 points) | D4: Read | E4: Measured | F4: V | G4: 4 | H4: 3 | I4: =G4*H4 | J4: -
A5: PV inverter NB01 to NB04 | B5: PLC box, Modbus TCP | C5: AC current L1, L2, L3 (3 points) | D5: Read | E5: Measured | F5: A | G5: 4 | H5: 3 | I5: =G5*H5 | J5: -
A6: PV inverter NB01 to NB04 | B6: PLC box, Modbus TCP | C6: Frequency | D6: Read | E6: Measured | F6: Hz | G6: 4 | H6: 1 | I6: =G6*H6 | J6: -
A7: PV inverter NB01 to NB04 | B7: PLC box, Modbus TCP | C7: Power factor | D7: Read | E7: Measured | F7: - | G7: 4 | H7: 1 | I7: =G7*H7 | J7: -
A8: PV inverter NB01 to NB04 | B8: PLC box, Modbus TCP | C8: DC voltage | D8: Read | E8: Measured | F8: V | G8: 4 | H8: 1 | I8: =G8*H8 | J8: -
A9: PV inverter NB01 to NB04 | B9: PLC box, Modbus TCP | C9: DC current | D9: Read | E9: Measured | F9: A | G9: 4 | H9: 1 | I9: =G9*H9 | J9: -
A10: PV inverter NB01 to NB04 | B10: PLC box, Modbus TCP | C10: DC power | D10: Read | E10: Measured | F10: kW | G10: 4 | H10: 1 | I10: =G10*H10 | J10: -
A11: PV inverter NB01 to NB04 | B11: PLC box, Modbus TCP | C11: Energy today | D11: Read | E11: Counter | F11: kWh | G11: 4 | H11: 1 | I11: =G11*H11 | J11: -
A12: PV inverter NB01 to NB04 | B12: PLC box, Modbus TCP | C12: Energy total | D12: Read | E12: Counter | F12: MWh | G12: 4 | H12: 1 | I12: =G12*H12 | J12: -
A13: PV inverter NB01 to NB04 | B13: PLC box, Modbus TCP | C13: Internal temperature | D13: Read | E13: Measured | F13: deg C | G13: 4 | H13: 1 | I13: =G13*H13 | J13: -
... A18: PV inverter NB01 to NB04 | B18: PLC box, Modbus TCP | C18: Communication healthy | D18: Read | E18: Status | F18: - | G18: 4 | H18: 1 | I18: =G18*H18 | J18: -
A19: PV inverter NB01 to NB04 | B19: PLC box, Modbus TCP | C19: Active power limit | D19: Write | E19: Setpoint | F19: % | G19: 4 | H19: 1 | I19: =G19*H19 | J19: Admin | K19: Normally set by the EMS; write only if the EMS allows
A20: PV inverter NB01 to NB04 | B20: PLC box, Modbus TCP | C20: Start / stop | D20: Write | E20: Command | F20: - | G20: 4 | H20: 1 | I20: =G20*H20 | J20: Admin
A21: Embedded EMS | B21: Modbus TCP | C21: Plant active power | D21: Read | E21: Measured | F21: kW | G21: 1 | H21: 1 | I21: =G21*H21 | J21: -
A22: Embedded EMS | B22: Modbus TCP | C22: Plant reactive power | D22: Read | E22: Measured | F22: kvar | G22: 1 | H22: 1 | I22: =G22*H22 | J22: -
A23: Embedded EMS | B23: Modbus TCP | C23: PV total power | D23: Read | E23: Measured | F23: kW | G23: 1 | H23: 1 | I23: =G23*H23 | J23: -
A24: Embedded EMS | B24: Modbus TCP | C24: BESS power | D24: Read | E24: Measured | F24: kW | G24: 1 | H24: 1 | I24: =G24*H24 | J24: -
A25: Embedded EMS | B25: Modbus TCP | C25: Generator total power | D25: Read | E25: Measured | F25: kW | G25: 1 | H25: 1 | I25: =G25*H25 | J25: -
A26: Embedded EMS | B26: Modbus TCP | C26: Load power | D26: Read | E26: Measured | F26: kW | G26: 1 | H26: 1 | I26: =G26*H26 | J26: -
A27: Embedded EMS | B27: Modbus TCP | C27: Bus voltage | D27: Read | E27: Measured | F27: kV | G27: 1 | H27: 1 | I27: =G27*H27 | J27: -
A28: Embedded EMS | B28: Modbus TCP | C28: Bus frequency | D28: Read | E28: Measured | F28: Hz | G28: 1 | H28: 1 | I28: =G28*H28 | J28: -
A29: Embedded EMS | B29: Modbus TCP | C29: Operating mode | D29: Read | E29: Status | F29: - | G29: 1 | H29: 1 | I29: =G29*H29 | J29: -
A30: Embedded EMS | B30: Modbus TCP | C30: EMS state | D30: Read | E30: Status | F30: - | G30: 1 | H30: 1 | I30: =G30*H30 | J30: -
A31: Embedded EMS | B31: Modbus TCP | C31: EMS summary alarm | D31: Read | E31: Status | F31: - | G31: 1 | H31: 1 | I31: =G31*H31 | J31: -
... A33: Embedded EMS | B33: Modbus TCP | C33: PV curtailment active | D33: Read | E33: Status | F33: - | G33: 1 | H33: 1 | I33: =G33*H33 | J33: -
A34: Embedded EMS | B34: Modbus TCP | C34: EMS heartbeat | D34: Read/Write | E34: Counter | F34: - | G34: 1 | H34: 1 | I34: =G34*H34 | J34: Automatic | K34: Link supervision
A35: Embedded EMS | B35: Modbus TCP | C35: Operating mode select | D35: Write | E35: Command | F35: - | G35: 1 | H35: 1 | I35: =G35*H35 | J35: Admin
A36: Embedded EMS | B36: Modbus TCP | C36: State of charge minimum | D36: Write | E36: Setpoint | F36: % | G36: 1 | H36: 1 | I36: =G36*H36 | J36: Admin
A37: Embedded EMS | B37: Modbus TCP | C37: State of charge maximum | D37: Write | E37: Setpoint | F37: % | G37: 1 | H37: 1 | I37: =G37*H37 | J37: Admin
A38: Embedded EMS | B38: Modbus TCP | C38: Generator start threshold | D38: Write | E38: Setpoint | F38: % | G38: 1 | H38: 1 | I38: =G38*H38 | J38: Admin
A39: Embedded EMS | B39: Modbus TCP | C39: Generator stop threshold | D39: Write | E39: Setpoint | F39: % | G39: 1 | H39: 1 | I39: =G39*H39 | J39: Admin
A40: Embedded EMS | B40: Modbus TCP | C40: BESS power limit | D40: Write | E40: Setpoint | F40: kW | G40: 1 | H40: 1 | I40: =G40*H40 | J40: Admin
A41: Embedded EMS | B41: Modbus TCP | C41: BESS C-rate limit enable / disable | D41: Write | E41: Command | F41: - | G41: 1 | H41: 1 | I41: =G41*H41 | J41: Admin | K41: Calibration only; available only if the EMS exposes it
A42: Embedded EMS | B42: Modbus TCP | C42: Fault reset, level 3 | D42: Write | E42: Command | F42: - | G42: 1 | H42: 1 | I42: =G42*H42 | J42: Operator
A43: Embedded EMS | B43: Modbus TCP | C43: Fault reset, levels 1 and 2 | D43: Write | E43: Command | F43: - | G43: 1 | H43: 1 | I43: =G43*H43 | J43: Admin
A44: Battery system ST3340UX | B44: Through the EMS, Modbus TCP | C44: State of charge | D44: Read | E44: Measured | F44: % | G44: 1 | H44: 1 | I44: =G44*H44 | J44: -
A45: Battery system ST3340UX | B45: Through the EMS, Modbus TCP | C45: State of health | D45: Read | E45: Measured | F45: % | G45: 1 | H45: 1 | I45: =G45*H45 | J45: -
...

Sheet Comms Point List
A1: Tag | B1: Device | C1: Point | D1: Direction | E1: Data type | F1: Unit | G1: Source / protocol | H1: Alarm level | I1: Alarm when | J1: Operated by | K1: Notes
A2: NB01-P | B2: PV inverter NB01 | C2: Active power | D2: Read | E2: Measured | F2: kW | G2: PLC box, Modbus TCP | H2: - | I2: - | J2: -
A3: NB01-Q | B3: PV inverter NB01 | C3: Reactive power | D3: Read | E3: Measured | F3: kvar | G3: PLC box, Modbus TCP | H3: - | I3: - | J3: -
A4: NB01-U-L1 | B4: PV inverter NB01 | C4: AC voltage L1, L2, L3 (3 points) | D4: Read | E4: Measured | F4: V | G4: PLC box, Modbus TCP | H4: - | I4: - | J4: -
A5: NB01-U-L2 | B5: PV inverter NB01 | C5: AC voltage L1, L2, L3 (3 points) | D5: Read | E5: Measured | F5: V | G5: PLC box, Modbus TCP | H5: - | I5: - | J5: -
A6: NB01-U-L3 | B6: PV inverter NB01 | C6: AC voltage L1, L2, L3 (3 points) | D6: Read | E6: Measured | F6: V | G6: PLC box, Modbus TCP | H6: - | I6: - | J6: -
A7: NB01-I-L1 | B7: PV inverter NB01 | C7: AC current L1, L2, L3 (3 points) | D7: Read | E7: Measured | F7: A | G7: PLC box, Modbus TCP | H7: - | I7: - | J7: -
A8: NB01-I-L2 | B8: PV inverter NB01 | C8: AC current L1, L2, L3 (3 points) | D8: Read | E8: Measured | F8: A | G8: PLC box, Modbus TCP | H8: - | I8: - | J8: -
A9: NB01-I-L3 | B9: PV inverter NB01 | C9: AC current L1, L2, L3 (3 points) | D9: Read | E9: Measured | F9: A | G9: PLC box, Modbus TCP | H9: - | I9: - | J9: -
A10: NB01-F | B10: PV inverter NB01 | C10: Frequency | D10: Read | E10: Measured | F10: Hz | G10: PLC box, Modbus TCP | H10: - | I10: - | J10: -
A11: NB01-PF | B11: PV inverter NB01 | C11: Power factor | D11: Read | E11: Measured | F11: - | G11: PLC box, Modbus TCP | H11: - | I11: - | J11: -
A12: NB01-U-DC | B12: PV inverter NB01 | C12: DC voltage | D12: Read | E12: Measured | F12: V | G12: PLC box, Modbus TCP | H12: - | I12: - | J12: -
A13: NB01-I-DC | B13: PV inverter NB01 | C13: DC current | D13: Read | E13: Measured | F13: A | G13: PLC box, Modbus TCP | H13: - | I13: - | J13: -
... A22: NB01-COMM-OK | B22: PV inverter NB01 | C22: Communication healthy | D22: Read | E22: Status | F22: - | G22: PLC box, Modbus TCP | H22: 2 | I22: Off | J22: -
A23: NB01-P-LIM-SP | B23: PV inverter NB01 | C23: Active power limit | D23: Write | E23: Setpoint | F23: % | G23: PLC box, Modbus TCP | H23: - | I23: - | J23: Admin | K23: Normally set by the EMS; write only if the EMS allows
A24: NB01-START-STOP-CMD | B24: PV inverter NB01 | C24: Start / stop | D24: Write | E24: Command | F24: - | G24: PLC box, Modbus TCP | H24: - | I24: - | J24: Admin
A25: NB02-P | B25: PV inverter NB02 | C25: Active power | D25: Read | E25: Measured | F25: kW | G25: PLC box, Modbus TCP | H25: - | I25: - | J25: -
A26: NB02-Q | B26: PV inverter NB02 | C26: Reactive power | D26: Read | E26: Measured | F26: kvar | G26: PLC box, Modbus TCP | H26: - | I26: - | J26: -
A27: NB02-U-L1 | B27: PV inverter NB02 | C27: AC voltage L1, L2, L3 (3 points) | D27: Read | E27: Measured | F27: V | G27: PLC box, Modbus TCP | H27: - | I27: - | J27: -
A28: NB02-U-L2 | B28: PV inverter NB02 | C28: AC voltage L1, L2, L3 (3 points) | D28: Read | E28: Measured | F28: V | G28: PLC box, Modbus TCP | H28: - | I28: - | J28: -
A29: NB02-U-L3 | B29: PV inverter NB02 | C29: AC voltage L1, L2, L3 (3 points) | D29: Read | E29: Measured | F29: V | G29: PLC box, Modbus TCP | H29: - | I29: - | J29: -
A30: NB02-I-L1 | B30: PV inverter NB02 | C30: AC current L1, L2, L3 (3 points) | D30: Read | E30: Measured | F30: A | G30: PLC box, Modbus TCP | H30: - | I30: - | J30: -
A31: NB02-I-L2 | B31: PV inverter NB02 | C31: AC current L1, L2, L3 (3 points) | D31: Read | E31: Measured | F31: A | G31: PLC box, Modbus TCP | H31: - | I31: - | J31: -
A32: NB02-I-L3 | B32: PV inverter NB02 | C32: AC current L1, L2, L3 (3 points) | D32: Read | E32: Measured | F32: A | G32: PLC box, Modbus TCP | H32: - | I32: - | J32: -
A33: NB02-F | B33: PV inverter NB02 | C33: Frequency | D33: Read | E33: Measured | F33: Hz | G33: PLC box, Modbus TCP | H33: - | I33: - | J33: -
A34: NB02-PF | B34: PV inverter NB02 | C34: Power factor | D34: Read | E34: Measured | F34: - | G34: PLC box, Modbus TCP | H34: - | I34: - | J34: -
A35: NB02-U-DC | B35: PV inverter NB02 | C35: DC voltage | D35: Read | E35: Measured | F35: V | G35: PLC box, Modbus TCP | H35: - | I35: - | J35: -
... A45: NB02-COMM-OK | B45: PV inverter NB02 | C45: Communication healthy | D45: Read | E45: Status | F45: - | G45: PLC box, Modbus TCP | H45: 2 | I45: Off | J45: -
A46: NB02-P-LIM-SP | B46: PV inverter NB02 | C46: Active power limit | D46: Write | E46: Setpoint | F46: % | G46: PLC box, Modbus TCP | H46: - | I46: - | J46: Admin | K46: Normally set by the EMS; write only if the EMS allows
A47: NB02-START-STOP-CMD | B47: PV inverter NB02 | C47: Start / stop | D47: Write | E47: Command | F47: - | G47: PLC box, Modbus TCP | H47: - | I47: - | J47: Admin
A48: NB03-P | B48: PV inverter NB03 | C48: Active power | D48: Read | E48: Measured | F48: kW | G48: PLC box, Modbus TCP | H48: - | I48: - | J48: -
A49: NB03-Q | B49: PV inverter NB03 | C49: Reactive power | D49: Read | E49: Measured | F49: kvar | G49: PLC box, Modbus TCP | H49: - | I49: - | J49: -
A50: NB03-U-L1 | B50: PV inverter NB03 | C50: AC voltage L1, L2, L3 (3 points) | D50: Read | E50: Measured | F50: V | G50: PLC box, Modbus TCP | H50: - | I50: - | J50: -
A51: NB03-U-L2 | B51: PV inverter NB03 | C51: AC voltage L1, L2, L3 (3 points) | D51: Read | E51: Measured | F51: V | G51: PLC box, Modbus TCP | H51: - | I51: - | J51: -
A52: NB03-U-L3 | B52: PV inverter NB03 | C52: AC voltage L1, L2, L3 (3 points) | D52: Read | E52: Measured | F52: V | G52: PLC box, Modbus TCP | H52: - | I52: - | J52: -
A53: NB03-I-L1 | B53: PV inverter NB03 | C53: AC current L1, L2, L3 (3 points) | D53: Read | E53: Measured | F53: A | G53: PLC box, Modbus TCP | H53: - | I53: - | J53: -
A54: NB03-I-L2 | B54: PV inverter NB03 | C54: AC current L1, L2, L3 (3 points) | D54: Read | E54: Measured | F54: A | G54: PLC box, Modbus TCP | H54: - | I54: - | J54: -
A55: NB03-I-L3 | B55: PV inverter NB03 | C55: AC current L1, L2, L3 (3 points) | D55: Read | E55: Measured | F55: A | G55: PLC box, Modbus TCP | H55: - | I55: - | J55: -
A56: NB03-F | B56: PV inverter NB03 | C56: Frequency | D56: Read | E56: Measured | F56: Hz | G56: PLC box, Modbus TCP | H56: - | I56: - | J56: -
A57: NB03-PF | B57: PV inverter NB03 | C57: Power factor | D57: Read | E57: Measured | F57: - | G57: PLC box, Modbus TCP | H57: - | I57: - | J57: -
...

Sheet Datasheets
A1: No. | B1: Group | C1: Item | D1: Manufacturer | E1: Model | F1: Order no. to search | G1: Documents to collect | H1: Where to download | I1: Collected
A2: 1 | B2: Controller | C2: Processor module | D2: Siemens | E2: SICAM A8000 CP-8050 | F2: 6MF2805-0AA00 | G2: Datasheet; CP-8050 system manual; security manual | H2: Siemens Industry Online Support (support.industry.siemens.com): search the order number, tab 'Product information' or 'Manuals'
A3: 2 | B3: Controller | C3: Power supply | D3: Siemens | E3: SICAM A8000 PS-8642 | F3: 6MF2864-2AA00 | G3: Datasheet | H3: Siemens Industry Online Support (support.industry.siemens.com): search the order number, tab 'Product information' or 'Manuals'
A4: 3 | B4: Controller | C4: Ethernet interface | D4: Siemens | E4: SICAM A8000 CI-8520 | F4: 6MF2852-0AA00 | G4: Datasheet | H4: Siemens Industry Online Support (support.industry.siemens.com): search the order number, tab 'Product information' or 'Manuals'
A5: 4 | B5: Controller | C5: Flash card | D5: Siemens | E5: SICAM flash card 2 GB | F5: 6MF1213-1GA05-0AA0 | G5: Datasheet | H5: Siemens Industry Online Support (support.industry.siemens.com): search the order number, tab 'Product information' or 'Manuals'
A6: 5 | B6: I/O | C6: Digital input module | D6: Siemens | E6: SICAM A8000 DI-8112 | F6: 6MF2811-2AA00 | G6: Datasheet (confirm input voltage) | H6: Siemens Industry Online Support (support.industry.siemens.com): search the order number, tab 'Product information' or 'Manuals'
A7: 6 | B7: I/O | C7: Secured command output | D7: Siemens | E7: SICAM A8000 DO-8221 | F7: Ask Siemens | G7: Datasheet | H7: Siemens Industry Online Support (support.industry.siemens.com): search the order number, tab 'Product information' or 'Manuals'
A8: 7 | B8: I/O | C8: Relay output module | D8: Siemens | E8: SICAM A8000 DO-8212 | F8: 6MF2821-2AA00 | G8: Datasheet | H8: Siemens Industry Online Support (support.industry.siemens.com): search the order number, tab 'Product information' or 'Manuals'
A9: 8 | B9: I/O | C9: Analogue input module | D9: Siemens | E9: SICAM A8000 AI-8320 | F9: 6MF2832-0AA00 | G9: Datasheet | H9: Siemens Industry Online Support (support.industry.siemens.com): search the order number, tab 'Product information' or 'Manuals'
A10: 9 | B10: I/O | C10: Remote interface, electrical | D10: Siemens | E10: SICAM A8000 CI-8532 | F10: 6MF2853-2AA00 | G10: Datasheet | H10: Siemens Industry Online Support (support.industry.siemens.com): search the order number, tab 'Product information' or 'Manuals'
A11: 10 | B11: I/O | C11: Remote interface, optical | D11: Siemens | E11: SICAM A8000 CI-8533 | F11: Ask Siemens | G11: Datasheet, incl. fibre type and maximum length | H11: Siemens Industry Online Support (support.industry.siemens.com): search the order number, tab 'Product information' or 'Manuals'
A12: 11 | B12: I/O | C12: SICAM A8000 series | D12: Siemens | E12: SICAM A8000 catalogue | F12: - | G12: Catalogue / module overview | H12: Siemens SICAM A8000 product page (siemens.com, search 'SICAM A8000')
A13: 12 | B13: SCADA | C13: SCADA servers | D13: Siemens | E13: SIMATIC IPC647E | F13: Configured order no. | G13: Datasheet | H13: Siemens Industry Online Support (support.industry.siemens.com): search the order number, tab 'Product information' or 'Manuals'
... A43: 42 | B43: Field device | C43: Wind sensor | D43: Gill Instruments | E43: WindSonic RS485 | F43: - | G43: Datasheet | H43: gillinstruments.com product page
A45: Fill the Collected column as each file is saved. Name files '<No.>_<Model>.pdf' so they sort in this order inside the zip.
A46: Network items list both Siemens SCALANCE and Moxa/Fortinet; collect only the final choice.
